Exception ignored in running getpath:
Traceback (most recent call last):
  File "<frozen getpath>", line 357, in <module>
OSError: [Errno 8] Bad file descriptor
Fatal Python error: error evaluating path
Python runtime state: core initialized

Current thread 0x00000000 (most recent call first):
  <no Python frame>
