Fatal Python error: Failed to import encodings module
Python runtime state: core initialized
Traceback (most recent call last):
  File "<frozen importlib._bootstrap_external>", line 1514, in _path_importer_cache
KeyError: '/Lib/encodings'

During handling of the above exception, another exception occurred:

Traceback (most recent call last):
  File "/Lib/encodings/__init__.py", line 33, in <module>
  File "<frozen importlib._bootstrap>", line 1360, in _find_and_load
  File "<frozen importlib._bootstrap>", line 1322, in _find_and_load_unlocked
  File "<frozen importlib._bootstrap>", line 1262, in _find_spec
  File "<frozen importlib._bootstrap_external>", line 1557, in find_spec
  File "<frozen importlib._bootstrap_external>", line 1529, in _get_spec
  File "<frozen importlib._bootstrap_external>", line 1516, in _path_importer_cache
  File "<frozen importlib._bootstrap_external>", line 1492, in _path_hooks
  File "<frozen importlib._bootstrap_external>", line 1718, in path_hook_for_FileFinder
  File "<frozen importlib._bootstrap_external>", line 1602, in __init__
ValueError: generator already executing
